<?xml version="1.0"?>
<robot name="active_manual_wheelchair_proxy_visual">
  <!--
    Diagnostic playback wrapper.

    This keeps the same simplified physics layout as active_manual_wheelchair.urdf
    but renders the URDF proxy boxes/cylinders directly instead of the Free3D mesh.
  -->

  <material name="proxy_frame">
    <color rgba="0.95 0.52 0.10 1.0"/>
  </material>
  <material name="proxy_wheel">
    <color rgba="0.02 0.02 0.025 1.0"/>
  </material>
  <material name="proxy_handle">
    <color rgba="0.0 0.62 1.0 1.0"/>
  </material>

  <link name="base_link">
    <inertial>
      <origin xyz="0.00 0.00 0.48" rpy="0 0 0"/>
      <mass value="12.0"/>
      <inertia ixx="1.11" ixy="0.0" ixz="0.0" iyy="1.45" iyz="0.0" izz="0.94"/>
    </inertial>
    <visual name="seat_proxy_visual">
      <origin xyz="0.05 0.00 0.48" rpy="0 0 0"/>
      <geometry>
        <box size="0.48 0.46 0.08"/>
      </geometry>
      <material name="proxy_frame"/>
    </visual>
    <visual name="backrest_proxy_visual">
      <origin xyz="-0.34 0.00 0.72" rpy="0 0 0"/>
      <geometry>
        <box size="0.07 0.50 0.44"/>
      </geometry>
      <material name="proxy_frame"/>
    </visual>
    <visual name="front_frame_proxy_visual">
      <origin xyz="0.34 0.00 0.25" rpy="0 0 0"/>
      <geometry>
        <box size="0.08 0.58 0.08"/>
      </geometry>
      <material name="proxy_frame"/>
    </visual>
    <visual name="left_side_frame_proxy_visual">
      <origin xyz="0.02 0.30 0.32" rpy="0 0 0"/>
      <geometry>
        <box size="0.66 0.06 0.08"/>
      </geometry>
      <material name="proxy_frame"/>
    </visual>
    <visual name="right_side_frame_proxy_visual">
      <origin xyz="0.02 -0.30 0.32" rpy="0 0 0"/>
      <geometry>
        <box size="0.66 0.06 0.08"/>
      </geometry>
      <material name="proxy_frame"/>
    </visual>
    <collision name="seat_collision">
      <origin xyz="0.05 0.00 0.48" rpy="0 0 0"/>
      <geometry>
        <box size="0.48 0.46 0.08"/>
      </geometry>
    </collision>
    <collision name="backrest_collision">
      <origin xyz="-0.34 0.00 0.72" rpy="0 0 0"/>
      <geometry>
        <box size="0.07 0.50 0.44"/>
      </geometry>
    </collision>
    <collision name="front_frame_collision">
      <origin xyz="0.34 0.00 0.25" rpy="0 0 0"/>
      <geometry>
        <box size="0.08 0.58 0.08"/>
      </geometry>
    </collision>
    <collision name="left_side_frame_collision">
      <origin xyz="0.02 0.30 0.32" rpy="0 0 0"/>
      <geometry>
        <box size="0.66 0.06 0.08"/>
      </geometry>
    </collision>
    <collision name="right_side_frame_collision">
      <origin xyz="0.02 -0.30 0.32" rpy="0 0 0"/>
      <geometry>
        <box size="0.66 0.06 0.08"/>
      </geometry>
    </collision>
  </link>

  <link name="left_rear_wheel">
    <inertial>
      <origin xyz="0 0 0" rpy="0 0 0"/>
      <mass value="1.2"/>
      <inertia ixx="0.029" ixy="0.0" ixz="0.0" iyy="0.058" iyz="0.0" izz="0.029"/>
    </inertial>
    <visual>
      <origin xyz="0 0 0" rpy="1.57079632679 0 0"/>
      <geometry>
        <cylinder radius="0.31" length="0.045"/>
      </geometry>
      <material name="proxy_wheel"/>
    </visual>
    <collision>
      <origin xyz="0 0 0" rpy="1.57079632679 0 0"/>
      <geometry>
        <cylinder radius="0.31" length="0.045"/>
      </geometry>
    </collision>
  </link>

  <link name="right_rear_wheel">
    <inertial>
      <origin xyz="0 0 0" rpy="0 0 0"/>
      <mass value="1.2"/>
      <inertia ixx="0.029" ixy="0.0" ixz="0.0" iyy="0.058" iyz="0.0" izz="0.029"/>
    </inertial>
    <visual>
      <origin xyz="0 0 0" rpy="1.57079632679 0 0"/>
      <geometry>
        <cylinder radius="0.31" length="0.045"/>
      </geometry>
      <material name="proxy_wheel"/>
    </visual>
    <collision>
      <origin xyz="0 0 0" rpy="1.57079632679 0 0"/>
      <geometry>
        <cylinder radius="0.31" length="0.045"/>
      </geometry>
    </collision>
  </link>

  <joint name="left_rear_wheel_joint" type="continuous">
    <origin xyz="-0.05 0.37 0.31" rpy="0 0 0"/>
    <parent link="base_link"/>
    <child link="left_rear_wheel"/>
    <axis xyz="0 1 0"/>
    <dynamics damping="0.02" friction="0.01"/>
  </joint>

  <joint name="right_rear_wheel_joint" type="continuous">
    <origin xyz="-0.05 -0.37 0.31" rpy="0 0 0"/>
    <parent link="base_link"/>
    <child link="right_rear_wheel"/>
    <axis xyz="0 1 0"/>
    <dynamics damping="0.02" friction="0.01"/>
  </joint>

  <link name="left_caster_yaw_link">
    <inertial>
      <origin xyz="0 0 0" rpy="0 0 0"/>
      <mass value="0.2"/>
      <inertia ixx="0.0004" ixy="0.0" ixz="0.0" iyy="0.0004" iyz="0.0" izz="0.0004"/>
    </inertial>
  </link>

  <link name="right_caster_yaw_link">
    <inertial>
      <origin xyz="0 0 0" rpy="0 0 0"/>
      <mass value="0.2"/>
      <inertia ixx="0.0004" ixy="0.0" ixz="0.0" iyy="0.0004" iyz="0.0" izz="0.0004"/>
    </inertial>
  </link>

  <joint name="left_caster_yaw_joint" type="continuous">
    <origin xyz="0.39 0.25 0.16" rpy="0 0 0"/>
    <parent link="base_link"/>
    <child link="left_caster_yaw_link"/>
    <axis xyz="0 0 1"/>
    <dynamics damping="0.04" friction="0.01"/>
  </joint>

  <joint name="right_caster_yaw_joint" type="continuous">
    <origin xyz="0.39 -0.25 0.16" rpy="0 0 0"/>
    <parent link="base_link"/>
    <child link="right_caster_yaw_link"/>
    <axis xyz="0 0 1"/>
    <dynamics damping="0.04" friction="0.01"/>
  </joint>

  <link name="left_front_caster">
    <inertial>
      <origin xyz="0 0 0" rpy="0 0 0"/>
      <mass value="0.35"/>
      <inertia ixx="0.0007" ixy="0.0" ixz="0.0" iyy="0.0010" iyz="0.0" izz="0.0007"/>
    </inertial>
    <visual>
      <origin xyz="0 0 0" rpy="1.57079632679 0 0"/>
      <geometry>
        <cylinder radius="0.075" length="0.035"/>
      </geometry>
      <material name="proxy_wheel"/>
    </visual>
    <collision>
      <origin xyz="0 0 0" rpy="1.57079632679 0 0"/>
      <geometry>
        <cylinder radius="0.075" length="0.035"/>
      </geometry>
    </collision>
  </link>

  <link name="right_front_caster">
    <inertial>
      <origin xyz="0 0 0" rpy="0 0 0"/>
      <mass value="0.35"/>
      <inertia ixx="0.0007" ixy="0.0" ixz="0.0" iyy="0.0010" iyz="0.0" izz="0.0007"/>
    </inertial>
    <visual>
      <origin xyz="0 0 0" rpy="1.57079632679 0 0"/>
      <geometry>
        <cylinder radius="0.075" length="0.035"/>
      </geometry>
      <material name="proxy_wheel"/>
    </visual>
    <collision>
      <origin xyz="0 0 0" rpy="1.57079632679 0 0"/>
      <geometry>
        <cylinder radius="0.075" length="0.035"/>
      </geometry>
    </collision>
  </link>

  <joint name="left_front_caster_joint" type="continuous">
    <origin xyz="0.00 0.00 -0.085" rpy="0 0 0"/>
    <parent link="left_caster_yaw_link"/>
    <child link="left_front_caster"/>
    <axis xyz="0 1 0"/>
    <dynamics damping="0.02" friction="0.01"/>
  </joint>

  <joint name="right_front_caster_joint" type="continuous">
    <origin xyz="0.00 0.00 -0.085" rpy="0 0 0"/>
    <parent link="right_caster_yaw_link"/>
    <child link="right_front_caster"/>
    <axis xyz="0 1 0"/>
    <dynamics damping="0.02" friction="0.01"/>
  </joint>

  <link name="left_handle_frame">
    <inertial>
      <origin xyz="0 0 0" rpy="0 0 0"/>
      <mass value="0.01"/>
      <inertia ixx="0.00001" ixy="0.0" ixz="0.0" iyy="0.00001" iyz="0.0" izz="0.00001"/>
    </inertial>
    <visual>
      <origin xyz="0 0 0" rpy="0 0 0"/>
      <geometry>
        <box size="0.18 0.055 0.055"/>
      </geometry>
      <material name="proxy_handle"/>
    </visual>
    <collision>
      <origin xyz="0 0 0" rpy="0 0 0"/>
      <geometry>
        <box size="0.18 0.055 0.055"/>
      </geometry>
    </collision>
  </link>

  <link name="right_handle_frame">
    <inertial>
      <origin xyz="0 0 0" rpy="0 0 0"/>
      <mass value="0.01"/>
      <inertia ixx="0.00001" ixy="0.0" ixz="0.0" iyy="0.00001" iyz="0.0" izz="0.00001"/>
    </inertial>
    <visual>
      <origin xyz="0 0 0" rpy="0 0 0"/>
      <geometry>
        <box size="0.18 0.055 0.055"/>
      </geometry>
      <material name="proxy_handle"/>
    </visual>
    <collision>
      <origin xyz="0 0 0" rpy="0 0 0"/>
      <geometry>
        <box size="0.18 0.055 0.055"/>
      </geometry>
    </collision>
  </link>

  <joint name="left_handle_frame_joint" type="fixed">
    <origin xyz="-0.40 0.24 0.92029" rpy="0 0 0"/>
    <parent link="base_link"/>
    <child link="left_handle_frame"/>
  </joint>

  <joint name="right_handle_frame_joint" type="fixed">
    <origin xyz="-0.40 -0.24 0.92029" rpy="0 0 0"/>
    <parent link="base_link"/>
    <child link="right_handle_frame"/>
  </joint>
</robot>
